Workbook

Sheet Sheet1
D1: 鷹揚(愉快) | E1: 月目標(5:00起き) | F1: 仕事 | H1: 行数 | I1: task | J1: daily | K1: 感想 | M1: 本のまとめ・振り返り | N1: 新しいことを勉強
A2: =YEAR(C2) -> 2024 | B2: =MONTH(C2) -> 10 | C2: 45595 | D2: 1 | F2: 78
A3: =YEAR(C3) -> 2024 | B3: =MONTH(C3) -> 10 | C3: =C2+1 -> 45596 | D3: 1 | F3: 60 | I3: 1
A4: =YEAR(C4) -> 2024 | B4: =MONTH(C4) -> 11 | C4: =C3+1 -> 45597 | D4: 1 | F4: 60 | I4: 1
A5: =YEAR(C5) -> 2024 | B5: =MONTH(C5) -> 11 | C5: 45598 | D5: 1 | F5: 50 | I5: 1
A6: =YEAR(C6) -> 2024 | B6: =MONTH(C6) -> 11 | C6: 45599 | D6: 1 | F6: 60 | I6: 1 | N6: エアコンの掃除を初めて完遂
A7: =YEAR(C7) -> 2024 | B7: =MONTH(C7) -> 11 | C7: 45600 | D7: 1 | E7: 0 | F7: 60 | I7: 1
A8: =YEAR(C8) -> 2024 | B8: =MONTH(C8) -> 11 | C8: =C7+1 -> 45601 | D8: 0 | E8: 0 | F8: 60 | I8: 1 | N8: 残業で家事が多い+おしっこ処理で苛々
A9: =YEAR(C9) -> 2024 | B9: =MONTH(C9) -> 11 | C9: =C8+1 -> 45602 | D9: 0 | E9: 0 | F9: 60 | I9: 1 | N9: 時間がなくて、自転車に乗るのが遅い長女がまた自転車を降りようとして苛々（落ちたものを拾ってくれようとしていた）。
A10: =YEAR(C10) -> 2024 | B10: =MONTH(C10) -> 11 | C10: =C9+1 -> 45603 | D10: 0 | E10: 0 | F10: 45 | I10: 1 | N10: 帰宅して公文をしないと言い出した長女を追い詰めてしまう。今日は寝不足のせいかよく泣いていたそう。
A11: =YEAR(C11) -> 2024 | B11: =MONTH(C11) -> 11 | C11: =C10+1 -> 45604 | D11: 0 | E11: 0 | F11: 60 | I11: 1 | N11: これが終わったら風呂に入ると言っていたのに新しいことを始めたため注意。泣き出す
A12: =YEAR(C12) -> 2024 | B12: =MONTH(C12) -> 11 | C12: =C11+1 -> 45605 | D12: 1 | E12: 0 | F12: 60 | I12: 1
A13: =YEAR(C13) -> 2024 | B13: =MONTH(C13) -> 11 | C13: =C12+1 -> 45606 | D13: 1 | E13: 0 | F13: 75 | I13: 1
A14: =YEAR(C14) -> 2024 | B14: =MONTH(C14) -> 11 | C14: =C13+1 -> 45607 | D14: 1 | E14: 0 | F14: 40 | I14: 1
A15: =YEAR(C15) -> 2024 | B15: =MONTH(C15) -> 11 | C15: =C14+1 -> 45608 | D15: 1 | E15: 0 | F15: 60 | I15: 1 | N15: 下の子が路上で泣いて動かないのを、鷹揚というより我慢。
A16: =YEAR(C16) -> 2024 | B16: =MONTH(C16) -> 11 | C16: =C15+1 -> 45609 | D16: 0 | E16: 1 | F16: 80 | I16: 1
A17: =YEAR(C17) -> 2024 | B17: =MONTH(C17) -> 11 | C17: =C16+1 -> 45610 | D17: 0 | E17: 0 | F17: 60 | I17: 0
A18: =YEAR(C18) -> 2024 | B18: =MONTH(C18) -> 11 | C18: =C17+1 -> 45611 | D18: 0 | E18: 0 | F18: 30 | I18: 0 | N18: ご飯を座って食べるかどうかで上の子が泣いても追及を止めなかった
A19: =YEAR(C19) -> 2024 | B19: =MONTH(C19) -> 11 | C19: =C18+1 -> 45612 | D19: 1 | E19: 0 | F19: 80 | I19: 1
A20: =YEAR(C20) -> 2024 | B20: =MONTH(C20) -> 11 | C20: =C19+1 -> 45613 | D20: 0 | E20: 0 | F20: 60 | I20: 1
A21: =YEAR(C21) -> 2024 | B21: =MONTH(C21) -> 11 | C21: =C20+1 -> 45614 | D21: 1 | E21: 0 | F21: 60 | I21: 0
A22: =YEAR(C22) -> 2024 | B22: =MONTH(C22) -> 11 | C22: =C21+1 -> 45615 | D22: 0 | E22: 0 | F22: 60 | I22: 1 | N22: 自転車後部シートにもたれかかるのを注意して喧嘩。乗る前に確認することに
A23: =YEAR(C23) -> 2024 | B23: =MONTH(C23) -> 11 | C23: =C22+1 -> 45616 | D23: 0 | E23: 0 | F23: 50 | I23: 0 | N23: 公文をしないことで苛々。フォークで水で飲んでいたためコップを取り上げ。
A24: =YEAR(C24) -> 2024 | B24: =MONTH(C24) -> 11 | C24: =C23+1 -> 45617 | D24: 1 | E24: 0 | F24: 30 | I24: 1
A25: =YEAR(C25) -> 2024 | B25: =MONTH(C25) -> 11 | C25: =C24+1 -> 45618 | D25: 1 | E25: 0 | F25: 30 | I25: 0
A26: =YEAR(C26) -> 2024 | B26: =MONTH(C26) -> 11 | C26: =C25+1 -> 45619 | D26: 0 | E26: 0 | F26: 40 | I26: 1 | N26: 拾っていた落ち葉等を、必要だとして手を払われて苛々
A27: =YEAR(C27) -> 2024 | B27: =MONTH(C27) -> 11 | C27: =C26+1 -> 45620 | D27: 1 | E27: 0 | F27: 50 | I27: 0
A28: =YEAR(C28) -> 2024 | B28: =MONTH(C28) -> 11 | C28: =C27+1 -> 45621 | D28: 1 | E28: 1 | F28: 90 | I28: 1
A29: =YEAR(C29) -> 2024 | B29: =MONTH(C29) -> 11 | C29: =C28+1 -> 45622 | D29: 1 | E29: 0 | F29: 40 | I29: 0
A30: =YEAR(C30) -> 2024 | B30: =MONTH(C30) -> 11 | C30: =C29+1 -> 45623 | D30: 0 | E30: 0 | F30: 40 | I30: 1
A31: =YEAR(C31) -> 2024 | B31: =MONTH(C31) -> 11 | C31: =C30+1 -> 45624 | D31: 1 | E31: 1 | F31: 60 | I31: 0
A32: =YEAR(C32) -> 2024 | B32: =MONTH(C32) -> 11 | C32: =C31+1 -> 45625 | D32: 0 | E32: 0 | F32: 45 | I32: 1 | N32: ママの話をろくに聞かず自分の話をしようとするところから始まり大泣き。下の子も大泣き。
A33: =YEAR(C33) -> 2024 | B33: =MONTH(C33) -> 11 | C33: =C32+1 -> 45626 | D33: 1 | E33: 0 | F33: 50 | I33: 1 | N33: レンタル布団ではしゃぐなどして
A34: =YEAR(C34) -> 2024 | B34: =MONTH(C34) -> 12 | C34: =C33+1 -> 45627 | D34: 1 | E34: 1 | F34: 60 | I34: 1
A35: =YEAR(C35) -> 2024 | B35: =MONTH(C35) -> 12 | C35: =C34+1 -> 45628 | D35: 0 | E35: 1 | F35: 60 | I35: 1 | N35: 疲れのせいか久しぶりに暴言を吐く。元は約束を守らずに片づけないことから。
A36: =YEAR(C36) -> 2024 | B36: =MONTH(C36) -> 12 | C36: =C35+1 -> 45629 | D36: 0 | E36: 0 | F36: 0 | I36: 0
A37: =YEAR(C37) -> 2024 | B37: =MONTH(C37) -> 12 | C37: =C36+1 -> 45630 | D37: 1 | E37: 0 | F37: 0 | I37: 1 | N37: 朝は怒ったが、夜は公文を渋る中、開始するまで我慢強く笑いながら相手できた。公文に集中しないと苛々してしまうので何とかしないと
A38: =YEAR(C38) -> 2024 | B38: =MONTH(C38) -> 12 | C38: =C37+1 -> 45631 | D38: 0 | E38: 0 | F38: 50 | I38: 1 | M38: 5時に起きたのに、二度寝してしまう | N38: 公文の途中で寝てしまうので、公文を辞めろと喧嘩に
A39: =YEAR(C39) -> 2024 | B39: =MONTH(C39) -> 12 | C39: =C38+1 -> 45632 | D39: 1 | E39: 0.25 | F39: 40 | I39: 1
A40: =YEAR(C40) -> 2024 | B40: =MONTH(C40) -> 12 | C40: =C39+1 -> 45633 | D40: 1 | E40: 0.23611111 | F40: 50 | I40: 1
...

Sheet Sheet2
A1: year | B1: month | D1: 鷹揚 | E1: 月目標(5:00起き) | F1: 仕事 | G1: 枚数 | H1: task
A2: 2024 | B2: 11 | C2: =A2&"_"&B2 -> 2024_11 | D2: =AVERAGEIFS(Sheet1!D:D,Sheet1!$A:$A,$A2,Sheet1!$B:$B,$B2) -> 0.56666667 | E2: =AVERAGEIFS(Sheet1!E:E,Sheet1!$A:$A,$A2,Sheet1!$B:$B,$B2) -> 0.11111111 | F2: =AVERAGEIFS(Sheet1!F:F,Sheet1!$A:$A,$A2,Sheet1!$B:$B,$B2) -> 54.833333 | H2: =AVERAGEIFS(Sheet1!I:I,Sheet1!$A:$A,$A2,Sheet1!$B:$B,$B2) -> 0.73333333
A3: 2024 | B3: 12 | C3: =A3&"_"&B3 -> 2024_12 | D3: =AVERAGEIFS(Sheet1!D:D,Sheet1!$A:$A,$A3,Sheet1!$B:$B,$B3) -> 0.64516129 | E3: =AVERAGEIFS(Sheet1!E:E,Sheet1!$A:$A,$A3,Sheet1!$B:$B,$B3) -> 0.27125896 | F3: =AVERAGEIFS(Sheet1!F:F,Sheet1!$A:$A,$A3,Sheet1!$B:$B,$B3) -> 53.709677 | H3: =AVERAGEIFS(Sheet1!I:I,Sheet1!$A:$A,$A3,Sheet1!$B:$B,$B3) -> 0.77419355
A4: 2025 | B4: 1 | C4: =A4&"_"&B4 -> 2025_1 | D4: =AVERAGEIFS(Sheet1!D:D,Sheet1!$A:$A,$A4,Sheet1!$B:$B,$B4) -> 0.70967742 | E4: =AVERAGEIFS(Sheet1!E:E,Sheet1!$A:$A,$A4,Sheet1!$B:$B,$B4) -> 0.2500448 | F4: =AVERAGEIFS(Sheet1!F:F,Sheet1!$A:$A,$A4,Sheet1!$B:$B,$B4) -> 55.483871 | H4: =AVERAGEIFS(Sheet1!I:I,Sheet1!$A:$A,$A4,Sheet1!$B:$B,$B4) -> 0.74193548
A5: 2025 | B5: 2 | C5: =A5&"_"&B5 -> 2025_2 | D5: =AVERAGEIFS(Sheet1!D:D,Sheet1!$A:$A,$A5,Sheet1!$B:$B,$B5) -> 0.71428571 | E5: =AVERAGEIFS(Sheet1!E:E,Sheet1!$A:$A,$A5,Sheet1!$B:$B,$B5) -> 0.25367063 | F5: =AVERAGEIFS(Sheet1!F:F,Sheet1!$A:$A,$A5,Sheet1!$B:$B,$B5) -> 55.714286 | H5: =AVERAGEIFS(Sheet1!I:I,Sheet1!$A:$A,$A5,Sheet1!$B:$B,$B5) -> 0.60714286
A6: 2025 | B6: 3 | C6: =A6&"_"&B6 -> 2025_3 | D6: =AVERAGEIFS(Sheet1!D:D,Sheet1!$A:$A,$A6,Sheet1!$B:$B,$B6) -> 0.74193548 | E6: =AVERAGEIFS(Sheet1!E:E,Sheet1!$A:$A,$A6,Sheet1!$B:$B,$B6) -> 0.26106631 | F6: =AVERAGEIFS(Sheet1!F:F,Sheet1!$A:$A,$A6,Sheet1!$B:$B,$B6) -> 51.548387 | G6: =AVERAGEIFS(Sheet1!H:H,Sheet1!$A:$A,$A6,Sheet1!$B:$B,$B6) -> 22.2 | H6: =AVERAGEIFS(Sheet1!I:I,Sheet1!$A:$A,$A6,Sheet1!$B:$B,$B6) -> 0.80645161
A7: 2025 | B7: 4 | C7: =A7&"_"&B7 -> 2025_4 | D7: =AVERAGEIFS(Sheet1!D:D,Sheet1!$A:$A,$A7,Sheet1!$B:$B,$B7) -> 0.62068966 | E7: =AVERAGEIFS(Sheet1!E:E,Sheet1!$A:$A,$A7,Sheet1!$B:$B,$B7) -> 0.25301724 | F7: =AVERAGEIFS(Sheet1!F:F,Sheet1!$A:$A,$A7,Sheet1!$B:$B,$B7) -> 77.241379 | G7: =AVERAGEIFS(Sheet1!H:H,Sheet1!$A:$A,$A7,Sheet1!$B:$B,$B7) -> 15.608696 | H7: =AVERAGEIFS(Sheet1!I:I,Sheet1!$A:$A,$A7,Sheet1!$B:$B,$B7) -> 0.62068966
A8: 2025 | B8: 5 | C8: =A8&"_"&B8 -> 2025_5 | D8: =AVERAGEIFS(Sheet1!D:D,Sheet1!$A:$A,$A8,Sheet1!$B:$B,$B8) -> 0.64285714 | E8: =AVERAGEIFS(Sheet1!E:E,Sheet1!$A:$A,$A8,Sheet1!$B:$B,$B8) -> 0.2264881 | F8: =AVERAGEIFS(Sheet1!F:F,Sheet1!$A:$A,$A8,Sheet1!$B:$B,$B8) -> 84.857143 | G8: =AVERAGEIFS(Sheet1!H:H,Sheet1!$A:$A,$A8,Sheet1!$B:$B,$B8) -> 0 | H8: =AVERAGEIFS(Sheet1!I:I,Sheet1!$A:$A,$A8,Sheet1!$B:$B,$B8) -> 0.71428571
A9: 2025 | B9: 6 | C9: =A9&"_"&B9 -> 2025_6 | D9: =AVERAGEIFS(Sheet1!D:D,Sheet1!$A:$A,$A9,Sheet1!$B:$B,$B9) -> 0.9 | E9: =AVERAGEIFS(Sheet1!E:E,Sheet1!$A:$A,$A9,Sheet1!$B:$B,$B9) -> 0.23074074 | F9: =AVERAGEIFS(Sheet1!F:F,Sheet1!$A:$A,$A9,Sheet1!$B:$B,$B9) -> 77.666667 | G9: =AVERAGEIFS(Sheet1!H:H,Sheet1!$A:$A,$A9,Sheet1!$B:$B,$B9) -> 0 | H9: =AVERAGEIFS(Sheet1!I:I,Sheet1!$A:$A,$A9,Sheet1!$B:$B,$B9) -> 0.53333333
A10: 2025 | B10: 7 | C10: =A10&"_"&B10 -> 2025_7 | D10: =AVERAGEIFS(Sheet1!D:D,Sheet1!$A:$A,$A10,Sheet1!$B:$B,$B10) -> 0.77419355 | E10: =AVERAGEIFS(Sheet1!E:E,Sheet1!$A:$A,$A10,Sheet1!$B:$B,$B10) -> 0.23931452 | F10: =AVERAGEIFS(Sheet1!F:F,Sheet1!$A:$A,$A10,Sheet1!$B:$B,$B10) -> 67.903226 | G10: =AVERAGEIFS(Sheet1!H:H,Sheet1!$A:$A,$A10,Sheet1!$B:$B,$B10) -> 8.3870968 | H10: =AVERAGEIFS(Sheet1!I:I,Sheet1!$A:$A,$A10,Sheet1!$B:$B,$B10) -> 0.61290323
A11: 2025 | B11: 8 | C11: =A11&"_"&B11 -> 2025_8 | D11: =AVERAGEIFS(Sheet1!D:D,Sheet1!$A:$A,$A11,Sheet1!$B:$B,$B11) -> 0.77272727 | E11: =AVERAGEIFS(Sheet1!E:E,Sheet1!$A:$A,$A11,Sheet1!$B:$B,$B11) -> 0.25226608 | F11: =AVERAGEIFS(Sheet1!F:F,Sheet1!$A:$A,$A11,Sheet1!$B:$B,$B11) -> 80.294118 | G11: =AVERAGEIFS(Sheet1!H:H,Sheet1!$A:$A,$A11,Sheet1!$B:$B,$B11) -> 10 | H11: =AVERAGEIFS(Sheet1!I:I,Sheet1!$A:$A,$A11,Sheet1!$B:$B,$B11) -> 0.77272727
A12: 2025 | B12: 9 | C12: =A12&"_"&B12 -> 2025_9 | D12: =AVERAGEIFS(Sheet1!D:D,Sheet1!$A:$A,$A12,Sheet1!$B:$B,$B12) -> 0.83333333 | E12: =AVERAGEIFS(Sheet1!E:E,Sheet1!$A:$A,$A12,Sheet1!$B:$B,$B12) -> 0.2412963 | F12: =AVERAGEIFS(Sheet1!F:F,Sheet1!$A:$A,$A12,Sheet1!$B:$B,$B12) -> 73.846154 | G12: =AVERAGEIFS(Sheet1!H:H,Sheet1!$A:$A,$A12,Sheet1!$B:$B,$B12) -> 20.428571 | H12: =AVERAGEIFS(Sheet1!I:I,Sheet1!$A:$A,$A12,Sheet1!$B:$B,$B12) -> 0.66666667
A13: 2025 | B13: 10 | C13: =A13&"_"&B13 -> 2025_10 | D13: =AVERAGEIFS(Sheet1!D:D,Sheet1!$A:$A,$A13,Sheet1!$B:$B,$B13) -> 0.77419355 | E13: =AVERAGEIFS(Sheet1!E:E,Sheet1!$A:$A,$A13,Sheet1!$B:$B,$B13) -> 0.2469086 | F13: =AVERAGEIFS(Sheet1!F:F,Sheet1!$A:$A,$A13,Sheet1!$B:$B,$B13) -> 69.677419 | G13: =AVERAGEIFS(Sheet1!H:H,Sheet1!$A:$A,$A13,Sheet1!$B:$B,$B13) -> #DIV/0! | H13: =AVERAGEIFS(Sheet1!I:I,Sheet1!$A:$A,$A13,Sheet1!$B:$B,$B13) -> 0.74193548
A14: =IF(B14=1,A13+1,A13) -> 2025 | B14: =IF(B13=12,1,B13+1) -> 11 | C14: =A14&"_"&B14 -> 2025_11 | D14: =AVERAGEIFS(Sheet1!D:D,Sheet1!$A:$A,$A14,Sheet1!$B:$B,$B14) -> 0.86666667 | E14: =AVERAGEIFS(Sheet1!E:E,Sheet1!$A:$A,$A14,Sheet1!$B:$B,$B14) -> 0.24704218 | F14: =AVERAGEIFS(Sheet1!F:F,Sheet1!$A:$A,$A14,Sheet1!$B:$B,$B14) -> 65.592593 | G14: =SUMIFS(Sheet1!H:H,Sheet1!$A:$A,$A14,Sheet1!$B:$B,$B14)/20 -> 19.95 | H14: =AVERAGEIFS(Sheet1!I:I,Sheet1!$A:$A,$A14,Sheet1!$B:$B,$B14) -> 0.7 | I14: 20までよくやった。まだ目が覚めてすぐ起きていない。妥協がある。仕事中の集中力に難あり。食事等に気をつける。余命短し
A15: =IF(B15=1,A14+1,A14) -> 2025 | B15: =IF(B14=12,1,B14+1) -> 12 | C15: =A15&"_"&B15 -> 2025_12 | D15: =AVERAGEIFS(Sheet1!D:D,Sheet1!$A:$A,$A15,Sheet1!$B:$B,$B15) -> 0.83870968 | E15: =AVERAGEIFS(Sheet1!E:E,Sheet1!$A:$A,$A15,Sheet1!$B:$B,$B15) -> 0.24121864 | F15: =AVERAGEIFS(Sheet1!F:F,Sheet1!$A:$A,$A15,Sheet1!$B:$B,$B15) -> 92.741935 | G15: =SUMIFS(Sheet1!H:H,Sheet1!$A:$A,$A15,Sheet1!$B:$B,$B15)/20 -> 28.9 | H15: =AVERAGEIFS(Sheet1!I:I,Sheet1!$A:$A,$A15,Sheet1!$B:$B,$B15) -> 0.70967742
A16: =IF(B16=1,A15+1,A15) -> 2026 | B16: =IF(B15=12,1,B15+1) -> 1 | C16: =A16&"_"&B16 -> 2026_1 | D16: =AVERAGEIFS(Sheet1!D:D,Sheet1!$A:$A,$A16,Sheet1!$B:$B,$B16) -> 0.90322581 | E16: =AVERAGEIFS(Sheet1!E:E,Sheet1!$A:$A,$A16,Sheet1!$B:$B,$B16) -> 0.22390233 | F16: =AVERAGEIFS(Sheet1!F:F,Sheet1!$A:$A,$A16,Sheet1!$B:$B,$B16) -> 101.12903 | G16: =SUMIFS(Sheet1!H:H,Sheet1!$A:$A,$A16,Sheet1!$B:$B,$B16)/20 -> 30.35 | H16: =AVERAGEIFS(Sheet1!I:I,Sheet1!$A:$A,$A16,Sheet1!$B:$B,$B16) -> 0.61290323
A17: =IF(B17=1,A16+1,A16) -> 2026 | B17: =IF(B16=12,1,B16+1) -> 2 | C17: =A17&"_"&B17 -> 2026_2 | D17: =AVERAGEIFS(Sheet1!D:D,Sheet1!$A:$A,$A17,Sheet1!$B:$B,$B17) -> 0.625 | E17: =AVERAGEIFS(Sheet1!E:E,Sheet1!$A:$A,$A17,Sheet1!$B:$B,$B17) -> 0.22920525 | F17: =AVERAGEIFS(Sheet1!F:F,Sheet1!$A:$A,$A17,Sheet1!$B:$B,$B17) -> 77.263158 | G17: =SUMIFS(Sheet1!H:H,Sheet1!$A:$A,$A17,Sheet1!$B:$B,$B17)/20 -> 18.1 | H17: =AVERAGEIFS(Sheet1!I:I,Sheet1!$A:$A,$A17,Sheet1!$B:$B,$B17) -> 0.69230769
A18: =IF(B18=1,A17+1,A17) -> 2026 | B18: =IF(B17=12,1,B17+1) -> 3 | C18: =A18&"_"&B18 -> 2026_3 | D18: =AVERAGEIFS(Sheet1!D:D,Sheet1!$A:$A,$A18,Sheet1!$B:$B,$B18) -> 0.74074074 | E18: =AVERAGEIFS(Sheet1!E:E,Sheet1!$A:$A,$A18,Sheet1!$B:$B,$B18) -> 0.24097222 | F18: =AVERAGEIFS(Sheet1!F:F,Sheet1!$A:$A,$A18,Sheet1!$B:$B,$B18) -> 64.62963 | G18: =SUMIFS(Sheet1!H:H,Sheet1!$A:$A,$A18,Sheet1!$B:$B,$B18)/20 -> 16.4 | H18: =AVERAGEIFS(Sheet1!I:I,Sheet1!$A:$A,$A18,Sheet1!$B:$B,$B18) -> 0.76
A19: =IF(B19=1,A18+1,A18) -> 2026 | B19: =IF(B18=12,1,B18+1) -> 4 | C19: =A19&"_"&B19 -> 2026_4 | D19: =AVERAGEIFS(Sheet1!D:D,Sheet1!$A:$A,$A19,Sheet1!$B:$B,$B19) -> 0.76666667 | E19: =AVERAGEIFS(Sheet1!E:E,Sheet1!$A:$A,$A19,Sheet1!$B:$B,$B19) -> 0.21300287 | F19: =AVERAGEIFS(Sheet1!F:F,Sheet1!$A:$A,$A19,Sheet1!$B:$B,$B19) -> 108.10345 | G19: =SUMIFS(Sheet1!H:H,Sheet1!$A:$A,$A19,Sheet1!$B:$B,$B19)/20 -> 5.1 | H19: =AVERAGEIFS(Sheet1!I:I,Sheet1!$A:$A,$A19,Sheet1!$B:$B,$B19) -> 0.83333333
A20: =IF(B20=1,A19+1,A19) -> 2026 | B20: =IF(B19=12,1,B19+1) -> 5 | C20: =A20&"_"&B20 -> 2026_5 | D20: =AVERAGEIFS(Sheet1!D:D,Sheet1!$A:$A,$A20,Sheet1!$B:$B,$B20) -> 0.82758621 | E20: =AVERAGEIFS(Sheet1!E:E,Sheet1!$A:$A,$A20,Sheet1!$B:$B,$B20) -> 0.21740591 | F20: =AVERAGEIFS(Sheet1!F:F,Sheet1!$A:$A,$A20,Sheet1!$B:$B,$B20) -> 94.032258 | G20: =SUMIFS(Sheet1!H:H,Sheet1!$A:$A,$A20,Sheet1!$B:$B,$B20)/20 -> 0 | H20: =AVERAGEIFS(Sheet1!I:I,Sheet1!$A:$A,$A20,Sheet1!$B:$B,$B20) -> 0.83870968
A21: =IF(B21=1,A20+1,A20) -> 2026 | B21: =IF(B20=12,1,B20+1) -> 6 | C21: =A21&"_"&B21 -> 2026_6 | D21: =AVERAGEIFS(Sheet1!D:D,Sheet1!$A:$A,$A21,Sheet1!$B:$B,$B21) -> 0.26666667 | E21: =AVERAGEIFS(Sheet1!E:E,Sheet1!$A:$A,$A21,Sheet1!$B:$B,$B21) -> 0.1912963 | F21: =AVERAGEIFS(Sheet1!F:F,Sheet1!$A:$A,$A21,Sheet1!$B:$B,$B21) -> 139.5 | G21: =SUMIFS(Sheet1!H:H,Sheet1!$A:$A,$A21,Sheet1!$B:$B,$B21)/20 -> 44 | H21: =AVERAGEIFS(Sheet1!I:I,Sheet1!$A:$A,$A21,Sheet1!$B:$B,$B21) -> 0.76666667
A22: =IF(B22=1,A21+1,A21) -> 2026 | B22: =IF(B21=12,1,B21+1) -> 7 | C22: =A22&"_"&B22 -> 2026_7 | D22: =AVERAGEIFS(Sheet1!D:D,Sheet1!$A:$A,$A22,Sheet1!$B:$B,$B22) -> 0.41935484 | E22: =AVERAGEIFS(Sheet1!E:E,Sheet1!$A:$A,$A22,Sheet1!$B:$B,$B22) -> 0.19491487 | F22: =AVERAGEIFS(Sheet1!F:F,Sheet1!$A:$A,$A22,Sheet1!$B:$B,$B22) -> 113.06452 | G22: =SUMIFS(Sheet1!H:H,Sheet1!$A:$A,$A22,Sheet1!$B:$B,$B22)/20 -> 50.5 | H22: =AVERAGEIFS(Sheet1!I:I,Sheet1!$A:$A,$A22,Sheet1!$B:$B,$B22) -> 0.80645161
J23: 1 こちらの意向に反する、無視する | M23: 文学
J24: 2 攻撃してくる | M24: 英語復習
J25: 3 過剰な要求 | M25: 日々の用事
J26: 4 こちらの機嫌が悪い | M26: 日記などの整理
J27: 5 discommunication | M27: 筋トレ
M28: thought

Sheet Sheet3
A1: year | B1: month | D1: 鷹揚(愉快) | E1: 月目標(5:00起き) | F1: 仕事 | H1: 枚数 | I1: task | J1: 筋トレ1 | K1: 筋トレ2 | L1: 英語1 | M1: 英語2(復習 | N1: 日記 | O1: 写真 | P1: 記事 | Q1: 感想 | S1: 本のまとめ・振り返り | T1: 新しいことを勉強
A2: 2024 | B2: 11
A3: 2024 | B3: 12
A4: 2025 | B4: 1
A5: 2025 | B5: 2
A6: 2025 | B6: 3
A7: 2025 | B7: 4
A8: 2025 | B8: 5
A9: 2025 | B9: 6
A10: 2025 | B10: 7
A11: 2025 | B11: 8
A12: 2025 | B12: 9
A13: 2025 | B13: 10
A14: =IF(B14=1,A13+1,A13) -> 2025 | B14: =IF(B13=12,1,B13+1) -> 11 | D14: 0.7 | E14: 0.22916667 | F14: 90 | H14: 20 | I14: 0.75 | J14: 20 | L14: 20 | S14: p15
A15: =IF(B15=1,A14+1,A14) -> 2025 | B15: =IF(B14=12,1,B14+1) -> 12 | H15: 25
A16: =IF(B16=1,A15+1,A15) -> 2026 | B16: =IF(B15=12,1,B15+1) -> 1 | H16: 30

Sheet Sheet4
A3: 5時に起きる！
B4: 11時に寝る
B5: 疲れた後はすぐ寝れなければテレビ、お笑いを見る
